<robot name="onshape">
    <link name="base">
        <visual>
            <origin xyz="0.138 0.123 0.037" rpy="0 0.261 -3.141" />
            <geometry>
                <mesh filename="package://base.stl" />
            </geometry>
            <material name="base_material">
                <color rgba="1 1 1 1" />
            </material>
        </visual>
        <collision>
            <origin xyz="0.138 0.123 0.037" rpy="0 0.261 -3.141" />
            <geometry>
                <mesh filename="package://base.stl" />
            </geometry>
        </collision>
        <inertial>
            <origin xyz="0 -0.017 -0.001" rpy="0 0 0" />
            <mass value="0.583" />
            <inertia ixx="0" ixy="0" ixz="0" iyy="0" iyz="0" izz="0" />
        </inertial>
    </link>

    <link name="upperarm">
        <visual>
            <origin xyz="-0.001 -0.292 -0.018" rpy="-1.57 0 -3.141" />
            <geometry>
                <mesh filename="package://_upperarm.stl" />
            </geometry>
            <material name="_upperarm_material">
                <color rgba="1 1 1 1" />
            </material>
        </visual>
        <collision>
            <origin xyz="-0.001 -0.292 -0.018" rpy="-1.57 0 -3.141" />
            <geometry>
                <mesh filename="package://_upperarm.stl" />
            </geometry>
        </collision>
        <visual>
            <origin xyz="0.007 -0.009 -0.012" rpy="-1.57 0 0" />
            <geometry>
                <mesh filename="package://motor.stl" />
            </geometry>
            <material name="motor_material">
                <color rgba="1 1 1 1" />
            </material>
        </visual>
        <collision>
            <origin xyz="0.007 -0.009 -0.012" rpy="-1.57 0 0" />
            <geometry>
                <mesh filename="package://motor.stl" />
            </geometry>
        </collision>
        <visual>
            <origin xyz="-0.007 -0.29 -0.012" rpy="-1.57 0 -3.141" />
            <geometry>
                <mesh filename="package://motor.stl" />
            </geometry>
            <material name="motor_material">
                <color rgba="1 1 1 1" />
            </material>
        </visual>
        <collision>
            <origin xyz="-0.007 -0.29 -0.012" rpy="-1.57 0 -3.141" />
            <geometry>
                <mesh filename="package://motor.stl" />
            </geometry>
        </collision>
        <visual>
            <origin xyz="0.001 -0.007 -0.018" rpy="-1.57 0 0" />
            <geometry>
                <mesh filename="package://_upperarm.stl" />
            </geometry>
            <material name="_upperarm_material">
                <color rgba="1 1 1 1" />
            </material>
        </visual>
        <collision>
            <origin xyz="0.001 -0.007 -0.018" rpy="-1.57 0 0" />
            <geometry>
                <mesh filename="package://_upperarm.stl" />
            </geometry>
        </collision>
        <inertial>
            <origin xyz="0 -0.149 -0.019" rpy="0 0 0" />
            <mass value="1.094" />
            <inertia ixx="0.013" ixy="0" ixz="0" iyy="0" iyz="0" izz="0.013" />
        </inertial>
    </link>

    <link name="link_0">
        <visual>
            <origin xyz="-0.001 0.004 -0.007" rpy="-3.141 -1.57 0" />
            <geometry>
                <mesh filename="package://motor.stl" />
            </geometry>
            <material name="motor_material">
                <color rgba="1 1 1 1" />
            </material>
        </visual>
        <collision>
            <origin xyz="-0.001 0.004 -0.007" rpy="-3.141 -1.57 0" />
            <geometry>
                <mesh filename="package://motor.stl" />
            </geometry>
        </collision>
        <visual>
            <origin xyz="-0.073 -0.105 0.108" rpy="-1.57 -1.57 0" />
            <geometry>
                <mesh filename="package://link_6.stl" />
            </geometry>
            <material name="link_6_material">
                <color rgba="1 1 1 1" />
            </material>
        </visual>
        <collision>
            <origin xyz="-0.073 -0.105 0.108" rpy="-1.57 -1.57 0" />
            <geometry>
                <mesh filename="package://link_6.stl" />
            </geometry>
        </collision>
        <inertial>
            <origin xyz="0 0.001 -0.014" rpy="0 0 0" />
            <mass value="0.175" />
            <inertia ixx="0" ixy="0" ixz="0" iyy="0" iyz="0" izz="0" />
        </inertial>
    </link>

    <link name="connection">
        <visual>
            <origin xyz="-0.001 0.025 0.02" rpy="-3.141 -0.011 0" />
            <geometry>
                <mesh filename="package://connection.stl" />
            </geometry>
            <material name="connection_material">
                <color rgba="1 1 1 1" />
            </material>
        </visual>
        <collision>
            <origin xyz="-0.001 0.025 0.02" rpy="-3.141 -0.011 0" />
            <geometry>
                <mesh filename="package://connection.stl" />
            </geometry>
        </collision>
        <inertial>
            <origin xyz="0 0.015 0.004" rpy="0 0 0" />
            <mass value="0.083" />
            <inertia ixx="0" ixy="0" ixz="0" iyy="0" iyz="0" izz="0" />
        </inertial>
    </link>

    <link name="forearm_right">
        <visual>
            <origin xyz="0.007 -0.009 -0.012" rpy="-1.57 0 0" />
            <geometry>
                <mesh filename="package://motor.stl" />
            </geometry>
            <material name="motor_material">
                <color rgba="1 1 1 1" />
            </material>
        </visual>
        <collision>
            <origin xyz="0.007 -0.009 -0.012" rpy="-1.57 0 0" />
            <geometry>
                <mesh filename="package://motor.stl" />
            </geometry>
        </collision>
        <visual>
            <origin xyz="0.005 -0.014 -0.301" rpy="3.141 0 -1.57" />
            <geometry>
                <mesh filename="package://motor.stl" />
            </geometry>
            <material name="motor_material">
                <color rgba="1 1 1 1" />
            </material>
        </visual>
        <collision>
            <origin xyz="0.005 -0.014 -0.301" rpy="3.141 0 -1.57" />
            <geometry>
                <mesh filename="package://motor.stl" />
            </geometry>
        </collision>
        <visual>
            <origin xyz="0 -0.009 -0.303" rpy="3.141 0 -1.57" />
            <geometry>
                <mesh filename="package://forearm_1.stl" />
            </geometry>
            <material name="forearm_1_material">
                <color rgba="1 1 1 1" />
            </material>
        </visual>
        <collision>
            <origin xyz="0 -0.009 -0.303" rpy="3.141 0 -1.57" />
            <geometry>
                <mesh filename="package://forearm_1.stl" />
            </geometry>
        </collision>
        <visual>
            <origin xyz="0 -0.009 -0.303" rpy="3.141 0 -1.57" />
            <geometry>
                <mesh filename="package://forearm_2.stl" />
            </geometry>
            <material name="forearm_2_material">
                <color rgba="1 1 1 1" />
            </material>
        </visual>
        <collision>
            <origin xyz="0 -0.009 -0.303" rpy="3.141 0 -1.57" />
            <geometry>
                <mesh filename="package://forearm_2.stl" />
            </geometry>
        </collision>
        <inertial>
            <origin xyz="0 -0.007 -0.145" rpy="0 0 0" />
            <mass value="1.381" />
            <inertia ixx="0.015" ixy="0" ixz="0" iyy="0.015" iyz="0" izz="0" />
        </inertial>
    </link>

    <link name="link_1">
        <visual>
            <origin xyz="0.001 0.004 -0.022" rpy="3.141 1.57 0" />
            <geometry>
                <mesh filename="package://motor.stl" />
            </geometry>
            <material name="motor_material">
                <color rgba="1 1 1 1" />
            </material>
        </visual>
        <collision>
            <origin xyz="0.001 0.004 -0.022" rpy="3.141 1.57 0" />
            <geometry>
                <mesh filename="package://motor.stl" />
            </geometry>
        </collision>
        <visual>
            <origin xyz="-0.073 -0.105 0.108" rpy="-1.57 -1.57 0" />
            <geometry>
                <mesh filename="package://link_6.stl" />
            </geometry>
            <material name="link_6_material">
                <color rgba="1 1 1 1" />
            </material>
        </visual>
        <collision>
            <origin xyz="-0.073 -0.105 0.108" rpy="-1.57 -1.57 0" />
            <geometry>
                <mesh filename="package://link_6.stl" />
            </geometry>
        </collision>
        <inertial>
            <origin xyz="0 0.001 -0.014" rpy="0 0 0" />
            <mass value="0.175" />
            <inertia ixx="0" ixy="0" ixz="0" iyy="0" iyz="0" izz="0" />
        </inertial>
    </link>

    <link name="wrist">
        <visual>
            <origin xyz="0.123 -0.065 -0.088" rpy="1.57 0 0" />
            <geometry>
                <mesh filename="package://wrist.stl" />
            </geometry>
            <material name="wrist_material">
                <color rgba="1 1 1 1" />
            </material>
        </visual>
        <collision>
            <origin xyz="0.123 -0.065 -0.088" rpy="1.57 0 0" />
            <geometry>
                <mesh filename="package://wrist.stl" />
            </geometry>
        </collision>
        <inertial>
            <origin xyz="-0.005 -0.071 -0.037" rpy="0 0 0" />
            <mass value="0.658" />
            <inertia ixx="0.001" ixy="0" ixz="0" iyy="0" iyz="0" izz="0" />
        </inertial>
    </link>

    <link name="ee_c">
        <visual>
            <origin xyz="0 0 -0.002" rpy="-1.57 0 0" />
            <geometry>
                <mesh filename="package://ee_c.stl" />
            </geometry>
            <material name="ee_c_material">
                <color rgba="0.796 0.823 0.937 1" />
            </material>
        </visual>
        <collision>
            <origin xyz="0 0 -0.002" rpy="-1.57 0 0" />
            <geometry>
                <mesh filename="package://ee_c.stl" />
            </geometry>
        </collision>
        <inertial>
            <origin xyz="0 0 -0.002" rpy="0 0 0" />
            <mass value="0" />
            <inertia ixx="0" ixy="0" ixz="0" iyy="0" iyz="0" izz="0" />
        </inertial>
    </link>

    <joint name="ee" type="revolute">
        <origin xyz="0 -0.123 -0.074" rpy="1.57 0 1.57" />
        <parent link="wrist" />
        <child link="ee_c" />
        <axis xyz="0 0 1" />
        <limit effort="1" velocity="20" lower="0" upper="0" />
        <joint_properties friction="0" />
    </joint>

    <joint name="6" type="revolute">
        <origin xyz="-0.007 0.017 -0.015" rpy="1.57 1.57 0" />
        <parent link="link_1" />
        <child link="wrist" />
        <axis xyz="0 0 1" />
        <limit effort="1" velocity="20" lower="-1.57" upper="1.57" />
        <joint_properties friction="0" />
    </joint>

    <joint name="5" type="revolute">
        <origin xyz="0.018 -0.007 -0.311" rpy="0 -1.57 0" />
        <parent link="forearm_right" />
        <child link="link_1" />
        <axis xyz="0 0 1" />
        <limit effort="1" velocity="20" lower="-1.57" upper="1.57" />
        <joint_properties friction="0" />
    </joint>

    <joint name="4" type="revolute">
        <origin xyz="0 0.025 0.02" rpy="1.57 -0.011 0" />
        <parent link="connection" />
        <child link="forearm_right" />
        <axis xyz="0 0 1" />
        <limit effort="1" velocity="20" lower="-1.57" upper="4.712" />
        <joint_properties friction="0" />
    </joint>

    <joint name="3" type="revolute">
        <origin xyz="0.007 0.017 -0.015" rpy="1.57 1.57 0" />
        <parent link="link_0" />
        <child link="connection" />
        <axis xyz="0 0 1" />
        <limit effort="1" velocity="20" lower="-1.57" upper="1.57" />
        <joint_properties friction="0" />
    </joint>

    <joint name="2" type="revolute">
        <origin xyz="0 -0.299 0" rpy="-3.141 0 0" />
        <parent link="upperarm" />
        <child link="link_0" />
        <axis xyz="0 0 1" />
        <limit effort="1" velocity="20" lower="-1.57" upper="1.57" />
        <joint_properties friction="0" />
    </joint>

    <joint name="1" type="revolute">
        <origin xyz="0.003 -0.054 -0.014" rpy="0 -0.261 0" />
        <parent link="base" />
        <child link="upperarm" />
        <axis xyz="0 0 1" />
        <limit effort="1" velocity="20" lower="-1.57" upper="3.141" />
        <joint_properties friction="0" />
    </joint>


</robot>